Traceback (most recent call last):
  File "/home/q20febvr/miniconda/lib/python3.10/site-packages/jupyter_cache/executors/utils.py", line 58, in single_nb_execution
    executenb(
  File "/home/q20febvr/miniconda/lib/python3.10/site-packages/nbclient/client.py", line 1265, in execute
    return NotebookClient(nb=nb, resources=resources, km=km, **kwargs).execute()
  File "/home/q20febvr/miniconda/lib/python3.10/site-packages/jupyter_core/utils/__init__.py", line 166, in wrapped
    return loop.run_until_complete(inner)
  File "/home/q20febvr/miniconda/lib/python3.10/asyncio/base_events.py", line 649, in run_until_complete
    return future.result()
  File "/home/q20febvr/miniconda/lib/python3.10/site-packages/nbclient/client.py", line 703, in async_execute
    await self.async_execute_cell(
  File "/home/q20febvr/miniconda/lib/python3.10/site-packages/nbclient/client.py", line 1021, in async_execute_cell
    await self._check_raise_for_error(cell, cell_index, exec_reply)
  File "/home/q20febvr/miniconda/lib/python3.10/site-packages/nbclient/client.py", line 915, in _check_raise_for_error
    raise CellExecutionError.from_cell_and_msg(cell, exec_reply_content)
nbclient.exceptions.CellExecutionError: An error occurred while executing the following cell:
------------------
# 2D map
bin_size = 1/20
(
    ds.sel(time='2017-01-01').assign(
        lat=ds.lat / bin_size // 1 * bin_size,
        lon=ds.lon / bin_size // 1 * bin_size
    )[['ssh', 'lat', 'lon']].load()
    .drop_vars('time')
    .to_dataframe()
    .groupby(['lat', 'lon']).mean()
    .to_xarray()
).ssh.plot()
------------------

[0;31m---------------------------------------------------------------------------[0m
[0;31mKeyError[0m                                  Traceback (most recent call last)
File [0;32m~/miniconda/envs/ocb-docs/lib/python3.11/site-packages/pandas/core/indexes/datetimes.py:610[0m, in [0;36mDatetimeIndex.get_loc[0;34m(self, key)[0m
[1;32m    609[0m [38;5;28;01mtry[39;00m:
[0;32m--> 610[0m     [38;5;28;01mreturn[39;00m [38;5;28;43mself[39;49m[38;5;241;43m.[39;49m[43m_partial_date_slice[49m[43m([49m[43mreso[49m[43m,[49m[43m [49m[43mparsed[49m[43m)[49m
[1;32m    611[0m [38;5;28;01mexcept[39;00m [38;5;167;01mKeyError[39;00m [38;5;28;01mas[39;00m err:

File [0;32m~/miniconda/envs/ocb-docs/lib/python3.11/site-packages/pandas/core/indexes/datetimelike.py:333[0m, in [0;36mDatetimeIndexOpsMixin._partial_date_slice[0;34m(self, reso, parsed)[0m
[1;32m    329[0m [38;5;28;01mif[39;00m [38;5;28mlen[39m([38;5;28mself[39m) [38;5;129;01mand[39;00m (
[1;32m    330[0m     (t1 [38;5;241m<[39m [38;5;28mself[39m[[38;5;241m0[39m] [38;5;129;01mand[39;00m t2 [38;5;241m<[39m [38;5;28mself[39m[[38;5;241m0[39m]) [38;5;129;01mor[39;00m (t1 [38;5;241m>[39m [38;5;28mself[39m[[38;5;241m-[39m[38;5;241m1[39m] [38;5;129;01mand[39;00m t2 [38;5;241m>[39m [38;5;28mself[39m[[38;5;241m-[39m[38;5;241m1[39m])
[1;32m    331[0m ):
[1;32m    332[0m     [38;5;66;03m# we are out of range[39;00m
[0;32m--> 333[0m     [38;5;28;01mraise[39;00m [38;5;167;01mKeyError[39;00m
[1;32m    335[0m [38;5;66;03m# TODO: does this depend on being monotonic _increasing_?[39;00m
[1;32m    336[0m 
[1;32m    337[0m [38;5;66;03m# a monotonic (sorted) series can be sliced[39;00m

[0;31mKeyError[0m: 

The above exception was the direct cause of the following exception:

[0;31mKeyError[0m                                  Traceback (most recent call last)
File [0;32m~/miniconda/envs/ocb-docs/lib/python3.11/site-packages/xarray/core/indexes.py:772[0m, in [0;36mPandasIndex.sel[0;34m(self, labels, method, tolerance)[0m
[1;32m    771[0m [38;5;28;01mtry[39;00m:
[0;32m--> 772[0m     indexer [38;5;241m=[39m [38;5;28;43mself[39;49m[38;5;241;43m.[39;49m[43mindex[49m[38;5;241;43m.[39;49m[43mget_loc[49m[43m([49m[43mlabel_value[49m[43m)[49m
[1;32m    773[0m [38;5;28;01mexcept[39;00m [38;5;167;01mKeyError[39;00m [38;5;28;01mas[39;00m e:

File [0;32m~/miniconda/envs/ocb-docs/lib/python3.11/site-packages/pandas/core/indexes/datetimes.py:612[0m, in [0;36mDatetimeIndex.get_loc[0;34m(self, key)[0m
[1;32m    611[0m     [38;5;28;01mexcept[39;00m [38;5;167;01mKeyError[39;00m [38;5;28;01mas[39;00m err:
[0;32m--> 612[0m         [38;5;28;01mraise[39;00m [38;5;167;01mKeyError[39;00m(key) [38;5;28;01mfrom[39;00m [38;5;21;01merr[39;00m
[1;32m    614[0m key [38;5;241m=[39m parsed

[0;31mKeyError[0m: '2017-01-01'

The above exception was the direct cause of the following exception:

[0;31mKeyError[0m                                  Traceback (most recent call last)
Cell [0;32mIn[3], line 4[0m
[1;32m      1[0m [38;5;66;03m# 2D map[39;00m
[1;32m      2[0m bin_size [38;5;241m=[39m [38;5;241m1[39m[38;5;241m/[39m[38;5;241m20[39m
[1;32m      3[0m (
[0;32m----> 4[0m     [43mds[49m[38;5;241;43m.[39;49m[43msel[49m[43m([49m[43mtime[49m[38;5;241;43m=[39;49m[38;5;124;43m'[39;49m[38;5;124;43m2017-01-01[39;49m[38;5;124;43m'[39;49m[43m)[49m[38;5;241m.[39massign(
[1;32m      5[0m         lat[38;5;241m=[39mds[38;5;241m.[39mlat [38;5;241m/[39m bin_size [38;5;241m/[39m[38;5;241m/[39m [38;5;241m1[39m [38;5;241m*[39m bin_size,
[1;32m      6[0m         lon[38;5;241m=[39mds[38;5;241m.[39mlon [38;5;241m/[39m bin_size [38;5;241m/[39m[38;5;241m/[39m [38;5;241m1[39m [38;5;241m*[39m bin_size
[1;32m      7[0m     )[[[38;5;124m'[39m[38;5;124mssh[39m[38;5;124m'[39m, [38;5;124m'[39m[38;5;124mlat[39m[38;5;124m'[39m, [38;5;124m'[39m[38;5;124mlon[39m[38;5;124m'[39m]][38;5;241m.[39mload()
[1;32m      8[0m     [38;5;241m.[39mdrop_vars([38;5;124m'[39m[38;5;124mtime[39m[38;5;124m'[39m)
[1;32m      9[0m     [38;5;241m.[39mto_dataframe()
[1;32m     10[0m     [38;5;241m.[39mgroupby([[38;5;124m'[39m[38;5;124mlat[39m[38;5;124m'[39m, [38;5;124m'[39m[38;5;124mlon[39m[38;5;124m'[39m])[38;5;241m.[39mmean()
[1;32m     11[0m     [38;5;241m.[39mto_xarray()
[1;32m     12[0m )[38;5;241m.[39mssh[38;5;241m.[39mplot()

File [0;32m~/miniconda/envs/ocb-docs/lib/python3.11/site-packages/xarray/core/dataset.py:3097[0m, in [0;36mDataset.sel[0;34m(self, indexers, method, tolerance, drop, **indexers_kwargs)[0m
[1;32m   3029[0m [38;5;250m[39m[38;5;124;03m"""Returns a new dataset with each array indexed by tick labels[39;00m
[1;32m   3030[0m [38;5;124;03malong the specified dimension(s).[39;00m
[1;32m   3031[0m 
[0;32m   (...)[0m
[1;32m   3094[0m 
[1;32m   3095[0m [38;5;124;03m"""[39;00m
[1;32m   3096[0m indexers [38;5;241m=[39m either_dict_or_kwargs(indexers, indexers_kwargs, [38;5;124m"[39m[38;5;124msel[39m[38;5;124m"[39m)
[0;32m-> 3097[0m query_results [38;5;241m=[39m [43mmap_index_queries[49m[43m([49m
[1;32m   3098[0m [43m    [49m[38;5;28;43mself[39;49m[43m,[49m[43m [49m[43mindexers[49m[38;5;241;43m=[39;49m[43mindexers[49m[43m,[49m[43m [49m[43mmethod[49m[38;5;241;43m=[39;49m[43mmethod[49m[43m,[49m[43m [49m[43mtolerance[49m[38;5;241;43m=[39;49m[43mtolerance[49m
[1;32m   3099[0m [43m[49m[43m)[49m
[1;32m   3101[0m [38;5;28;01mif[39;00m drop:
[1;32m   3102[0m     no_scalar_variables [38;5;241m=[39m {}

File [0;32m~/miniconda/envs/ocb-docs/lib/python3.11/site-packages/xarray/core/indexing.py:192[0m, in [0;36mmap_index_queries[0;34m(obj, indexers, method, tolerance, **indexers_kwargs)[0m
[1;32m    190[0m         results[38;5;241m.[39mappend(IndexSelResult(labels))
[1;32m    191[0m     [38;5;28;01melse[39;00m:
[0;32m--> 192[0m         results[38;5;241m.[39mappend([43mindex[49m[38;5;241;43m.[39;49m[43msel[49m[43m([49m[43mlabels[49m[43m,[49m[43m [49m[38;5;241;43m*[39;49m[38;5;241;43m*[39;49m[43moptions[49m[43m)[49m)
[1;32m    194[0m merged [38;5;241m=[39m merge_sel_results(results)
[1;32m    196[0m [38;5;66;03m# drop dimension coordinates found in dimension indexers[39;00m
[1;32m    197[0m [38;5;66;03m# (also drop multi-index if any)[39;00m
[1;32m    198[0m [38;5;66;03m# (.sel() already ensures alignment)[39;00m

File [0;32m~/miniconda/envs/ocb-docs/lib/python3.11/site-packages/xarray/core/indexes.py:774[0m, in [0;36mPandasIndex.sel[0;34m(self, labels, method, tolerance)[0m
[1;32m    772[0m                 indexer [38;5;241m=[39m [38;5;28mself[39m[38;5;241m.[39mindex[38;5;241m.[39mget_loc(label_value)
[1;32m    773[0m             [38;5;28;01mexcept[39;00m [38;5;167;01mKeyError[39;00m [38;5;28;01mas[39;00m e:
[0;32m--> 774[0m                 [38;5;28;01mraise[39;00m [38;5;167;01mKeyError[39;00m(
[1;32m    775[0m                     [38;5;124mf[39m[38;5;124m"[39m[38;5;124mnot all values found in index [39m[38;5;132;01m{[39;00mcoord_name[38;5;132;01m!r}[39;00m[38;5;124m. [39m[38;5;124m"[39m
[1;32m    776[0m                     [38;5;124m"[39m[38;5;124mTry setting the `method` keyword argument (example: method=[39m[38;5;124m'[39m[38;5;124mnearest[39m[38;5;124m'[39m[38;5;124m).[39m[38;5;124m"[39m
[1;32m    777[0m                 ) [38;5;28;01mfrom[39;00m [38;5;21;01me[39;00m
[1;32m    779[0m [38;5;28;01melif[39;00m label_array[38;5;241m.[39mdtype[38;5;241m.[39mkind [38;5;241m==[39m [38;5;124m"[39m[38;5;124mb[39m[38;5;124m"[39m:
[1;32m    780[0m     indexer [38;5;241m=[39m label_array

[0;31mKeyError[0m: "not all values found in index 'time'. Try setting the `method` keyword argument (example: method='nearest')."
KeyError: "not all values found in index 'time'. Try setting the `method` keyword argument (example: method='nearest')."

